Workbook

Sheet 凡例
A1: キャンパス・スポットナビ 調査データ（survey.xlsx）
A3: ・spots シート：1行目が取込用の列名、2行目は日本語ラベル（取込時は2行目を読み飛ばす）。3行目以降がデータ。
A4: ・黄色のセル：空欄または「未調査」。要確認シートと併せて埋めていく。
A5: ・灰色の列（電源確保率）：参考表示のみで取込対象外。
A6: ・選択式の列はプルダウンで入力できる（選択肢シートで定義）。
A7: ・コンセント数は「実際に挿せる差込口の数」で統一（タップ数ベース）。
A8: ・元データ：21号館調査.xlsx／講義棟調査.xlsx／実験D調査報告書（久保田, 2026-09-25）。どの行がどれ由来かは source 列を参照、閲覧室図書館_ver2.xlsx（椅子・飲食・階を追加）。
A9: ・元データの解釈で判断した箇所は、すべて要確認シートに記載、閲覧室図書館_ver2.xlsx（椅子・飲食・階を追加）。
A10: ・reservations シート：CLASSの教室利用状況（2026/10/02 金）。授業・予約で使われている枠。

Sheet spots
A1: spot_id | B1: building | C1: floor | D1: area_name | E1: seats | F1: outlets | G1: chair_type | H1: standing | I1: quietness | J1: food | K1: task_light | L1: outlet_location | M1: note | N1: photo | O1: surveyed_at | P1: surveyor | Q1: source | R1: _power_ratio
A2: スポットID | B2: 建物 | C2: 階 | D2: エリア名 | E2: 座席数 | F2: コンセント数（使える差込口） | G2: 椅子の種類 | H2: 立ち作業 | I2: 静粛性 | J2: 飲食可否 | K2: 作業灯 | L2: コンセントの位置 | M2: 備考 | N2: 写真 | O2: 調査日 | P2: 調査者 | Q2: 元データ | R2: （参考）電源確保率
A3: S001 | B3: 21号館 | C3: 1 | D3: 自習教室（12・13教室） | E3: 44 | F3: 14 | G3: 木製椅子 | H3: 不可 | I3: 通話可 | J3: 食事可 | K3: 未調査 | L3: 窓以外の壁3面 | M3: 1階の自習教室。3人掛けの机に椅子2脚。利用者が少なく静か。 | Q3: 21号館調査.xlsx | R3: =IF(AND(ISNUMBER(E3),ISNUMBER(F3),E3>0),F3/E3,"") -> 0.31818182
A4: S002 | B4: 21号館 | C4: 2 | D4: 階段脇 立ち作業スペース | E4: 20 | F4: 8 | G4: なし | H4: 可 | I4: 通話可 | J4: 食事可 | K4: 未調査 | L4: 柱に2か所・付近の壁に2か所 | M4: 階段付近の立ち作業スペース。座席数は詰めた場合の人数。人目を気にするなら柱のコンセントのみ。廊下にもコンセントが多数ある。 | Q4: 21号館調査.xlsx | R4: =IF(AND(ISNUMBER(E4),ISNUMBER(F4),E4>0),F4/E4,"") -> 0.4
A5: S003 | B5: 21号館 | C5: 3 | D5: スタディプラザ1 | E5: 10 | F5: 8 | G5: クッション椅子 | H5: 不可 | I5: 通話可 | J5: 飲み物のみ | K5: 未調査 | L5: 横の壁の前後 | M5: 3階のガラス張りの部屋。座り心地の良い椅子（木製椅子が1脚混在）。飲み物は蓋付きのみ可。 | Q5: 21号館調査.xlsx | R5: =IF(AND(ISNUMBER(E5),ISNUMBER(F5),E5>0),F5/E5,"") -> 0.8
A6: S004 | B6: 21号館 | C6: 3 | D6: スタディプラザ2 | E6: 18 | F6: 12 | G6: クッション椅子 | H6: 不可 | I6: 通話可 | J6: 飲み物のみ | K6: 未調査 | L6: 横の壁の前・中・後 | M6: 3階のガラス張りの部屋。座り心地の良い椅子（木製椅子が2脚混在）。飲み物は蓋付きのみ可。 | Q6: 21号館調査.xlsx | R6: =IF(AND(ISNUMBER(E6),ISNUMBER(F6),E6>0),F6/E6,"") -> 0.66666667
A7: S005 | B7: 講義棟 | C7: 5 | D7: K501 | E7: 142 | F7: 10 | G7: 木製椅子 | H7: 不可 | I7: 会話可 | J7: 食事可 | K7: 未調査 | M7: 講義室。 | Q7: 講義棟調査.xlsx | R7: =IF(AND(ISNUMBER(E7),ISNUMBER(F7),E7>0),F7/E7,"") -> 0.070422535
A8: S006 | B8: 講義棟 | C8: 5 | D8: K502 | E8: 142 | F8: 10 | G8: 木製椅子 | H8: 不可 | I8: 会話可 | J8: 食事可 | K8: 未調査 | M8: 講義室。 | Q8: 講義棟調査.xlsx | R8: =IF(AND(ISNUMBER(E8),ISNUMBER(F8),E8>0),F8/E8,"") -> 0.070422535
A9: S007 | B9: 講義棟 | C9: 5 | D9: K503 | E9: 178 | F9: 10 | G9: 木製椅子 | H9: 不可 | I9: 会話可 | J9: 食事可 | K9: 未調査 | M9: 講義室。 | Q9: 講義棟調査.xlsx | R9: =IF(AND(ISNUMBER(E9),ISNUMBER(F9),E9>0),F9/E9,"") -> 0.056179775
A10: S008 | B10: 講義棟 | C10: 5 | D10: K504 | E10: 178 | F10: 10 | G10: 木製椅子 | H10: 不可 | I10: 会話可 | J10: 食事可 | K10: 未調査 | M10: 講義室。 | Q10: 講義棟調査.xlsx | R10: =IF(AND(ISNUMBER(E10),ISNUMBER(F10),E10>0),F10/E10,"") -> 0.056179775
A11: S009 | B11: 講義棟 | C11: 5 | D11: K505 | E11: 178 | F11: 10 | G11: 木製椅子 | H11: 不可 | I11: 会話可 | J11: 食事可 | K11: 未調査 | M11: 講義室。 | Q11: 講義棟調査.xlsx | R11: =IF(AND(ISNUMBER(E11),ISNUMBER(F11),E11>0),F11/E11,"") -> 0.056179775
A12: S010 | B12: 講義棟 | C12: 5 | D12: K506 | E12: 178 | F12: 10 | G12: 木製椅子 | H12: 不可 | I12: 会話可 | J12: 食事可 | K12: 未調査 | M12: 講義室。 | Q12: 講義棟調査.xlsx | R12: =IF(AND(ISNUMBER(E12),ISNUMBER(F12),E12>0),F12/E12,"") -> 0.056179775
A13: S011 | B13: 講義棟 | C13: 5 | D13: K507 | E13: 94 | F13: 10 | G13: 木製椅子 | H13: 不可 | I13: 会話可 | J13: 食事可 | K13: 未調査 | M13: 講義室。 | Q13: 講義棟調査.xlsx | R13: =IF(AND(ISNUMBER(E13),ISNUMBER(F13),E13>0),F13/E13,"") -> 0.10638298
A14: S012 | B14: 講義棟 | C14: 5 | D14: K508 | E14: 94 | F14: 10 | G14: 木製椅子 | H14: 不可 | I14: 会話可 | J14: 食事可 | K14: 未調査 | M14: 講義室。 | Q14: 講義棟調査.xlsx | R14: =IF(AND(ISNUMBER(E14),ISNUMBER(F14),E14>0),F14/E14,"") -> 0.10638298
A15: S013 | B15: 講義棟 | C15: 5 | D15: K509 | E15: 94 | F15: 10 | G15: 木製椅子 | H15: 不可 | I15: 会話可 | J15: 食事可 | K15: 未調査 | M15: 講義室。 | Q15: 講義棟調査.xlsx | R15: =IF(AND(ISNUMBER(E15),ISNUMBER(F15),E15>0),F15/E15,"") -> 0.10638298
A16: S014 | B16: 講義棟 | C16: 6 | D16: K602 | E16: 142 | F16: 10 | G16: 木製椅子 | H16: 不可 | I16: 会話可 | J16: 食事可 | K16: 未調査 | M16: 講義室。 | Q16: 講義棟調査.xlsx | R16: =IF(AND(ISNUMBER(E16),ISNUMBER(F16),E16>0),F16/E16,"") -> 0.070422535
A17: S015 | B17: 講義棟 | C17: 6 | D17: K603 | E17: 178 | F17: 10 | G17: 木製椅子 | H17: 不可 | I17: 会話可 | J17: 食事可 | K17: 未調査 | M17: 講義室。 | Q17: 講義棟調査.xlsx | R17: =IF(AND(ISNUMBER(E17),ISNUMBER(F17),E17>0),F17/E17,"") -> 0.056179775
A18: S016 | B18: 講義棟 | C18: 6 | D18: K604 | E18: 178 | F18: 10 | G18: 木製椅子 | H18: 不可 | I18: 会話可 | J18: 食事可 | K18: 未調査 | M18: 講義室。 | Q18: 講義棟調査.xlsx | R18: =IF(AND(ISNUMBER(E18),ISNUMBER(F18),E18>0),F18/E18,"") -> 0.056179775
... A29: S027 | B29: 講義棟 | C29: 7 | D29: K705 | E29: 160 | F29: 220 | G29: 机一体型 | H29: 不可 | I29: 会話可 | J29: 食事可 | K29: 未調査 | M29: 講義室。 | Q29: 講義棟調査.xlsx | R29: =IF(AND(ISNUMBER(E29),ISNUMBER(F29),E29>0),F29/E29,"") -> 1.375
A30: S028 | B30: 講義棟 | C30: 7 | D30: K706 | F30: 10 | G30: 木製椅子 | H30: 不可 | I30: 会話可 | J30: 食事可 | K30: 未調査 | M30: 講義室。 | Q30: 講義棟調査.xlsx | R30: =IF(AND(ISNUMBER(E30),ISNUMBER(F30),E30>0),F30/E30,"")
A31: S029 | B31: 講義棟 | C31: 7 | D31: K707 | E31: 32 | F31: 10 | G31: キャスター付き椅子 | H31: 不可 | I31: 会話可 | J31: 食事可 | K31: 未調査 | M31: 講義室。 | Q31: 講義棟調査.xlsx | R31: =IF(AND(ISNUMBER(E31),ISNUMBER(F31),E31>0),F31/E31,"") -> 0.3125
A32: S030 | B32: 講義棟 | C32: 7 | D32: K708 | E32: 30 | F32: 10 | G32: キャスター付き椅子 | H32: 不可 | I32: 会話可 | J32: 食事可 | K32: 未調査 | M32: 講義室。 | Q32: 講義棟調査.xlsx | R32: =IF(AND(ISNUMBER(E32),ISNUMBER(F32),E32>0),F32/E32,"") -> 0.33333333
A33: S031 | B33: 講義棟 | C33: 7 | D33: K709 | E33: 32 | F33: 10 | G33: キャスター付き椅子 | H33: 不可 | I33: 会話可 | J33: 食事可 | K33: 未調査 | M33: 講義室。 | Q33: 講義棟調査.xlsx | R33: =IF(AND(ISNUMBER(E33),ISNUMBER(F33),E33>0),F33/E33,"") -> 0.3125
A34: S032 | B34: 閲覧室（建物未記入） | C34: 1 | D34: 6人掛けデスク | E34: 126 | F34: 168 | G34: クッション椅子 | H34: 不可 | I34: 通話可 | J34: 不可 | K34: あり | L34: 座席間に1口 | M34: 椅子：背もたれあり・座面にクッション。窓際5台・中央16台の計21台。建物内にゴミ箱・自動販売機あり。利用者が多く、毎回かなりうるさい。 | O34: 2026-09-25 | P34: 久保田 | Q34: 実験D調査報告書(2026-09-25)＋佐藤 聞き取り（静粛性）＋閲覧室図書館_ver2.xlsx | R34: =IF(AND(ISNUMBER(E34),ISNUMBER(F34),E34>0),F34/E34,"") -> 1.3333333
A35: S033 | B35: 閲覧室（建物未記入） | C35: 1 | D35: 2人掛けデスク | E35: 28 | F35: 28 | G35: クッション椅子 | H35: 不可 | I35: 通話可 | J35: 不可 | K35: あり | L35: 座席間に1口 | M35: 椅子：背もたれあり・座面にクッション。14台。LAN端子らしきメス端子が2口ある（使用可否は未確認）。利用者が多く、毎回かなりうるさい。 | O35: 2026-09-25 | P35: 久保田 | Q35: 実験D調査報告書(2026-09-25)＋佐藤 聞き取り（静粛性）＋閲覧室図書館_ver2.xlsx | R35: =IF(AND(ISNUMBER(E35),ISNUMBER(F35),E35>0),F35/E35,"") -> 1
A36: S034 | B36: 閲覧室（建物未記入） | C36: 1 | D36: ソファ（3人掛け） | E36: 12 | F36: 0 | G36: ソファ | H36: 不可 | I36: 通話可 | J36: 不可 | K36: なし | M36: 椅子：背もたれあり・座面と背もたれがクッション。4脚。利用者が多く、毎回かなりうるさい。 | O36: 2026-09-25 | P36: 久保田 | Q36: 実験D調査報告書(2026-09-25)＋佐藤 聞き取り（静粛性）＋閲覧室図書館_ver2.xlsx | R36: =IF(AND(ISNUMBER(E36),ISNUMBER(F36),E36>0),F36/E36,"") -> 0
A37: S035 | B37: 閲覧室（建物未記入） | C37: 1 | D37: ソファ（2人掛け） | E37: 8 | F37: 0 | G37: ソファ | H37: 不可 | I37: 通話可 | J37: 不可 | K37: なし | M37: 椅子：背もたれあり・座面と背もたれがクッション。4脚。利用者が多く、毎回かなりうるさい。 | O37: 2026-09-25 | P37: 久保田 | Q37: 実験D調査報告書(2026-09-25)＋佐藤 聞き取り（静粛性）＋閲覧室図書館_ver2.xlsx | R37: =IF(AND(ISNUMBER(E37),ISNUMBER(F37),E37>0),F37/E37,"") -> 0
A38: S036 | B38: 閲覧室（建物未記入） | C38: 1 | D38: ラウンジチェア | E38: 8 | F38: 0 | G38: ソファ | H38: 不可 | I38: 通話可 | J38: 不可 | K38: なし | M38: 椅子：背もたれあり・ひじ掛けあり。8脚。利用者が多く、毎回かなりうるさい。 | O38: 2026-09-25 | P38: 久保田 | Q38: 実験D調査報告書(2026-09-25)＋佐藤 聞き取り（静粛性）＋閲覧室図書館_ver2.xlsx | R38: =IF(AND(ISNUMBER(E38),ISNUMBER(F38),E38>0),F38/E38,"") -> 0
A39: S037 | B39: 自習室（建物未記入） | D39: 自習室 | E39: 60 | F39: 0 | G39: 未調査 | H39: 不可 | I39: 未調査 | J39: 未調査 | K39: 未調査 | M39: 6名掛けデスク10台。電源なし。 | O39: 2026-09-25 | P39: 久保田 | Q39: 実験D調査報告書(2026-09-25) | R39: =IF(AND(ISNUMBER(E39),ISNUMBER(F39),E39>0),F39/E39,"") -> 0
A40: S038 | B40: 図書館 | C40: 1 | D40: 入り口右手 | E40: 48 | F40: 0 | G40: 通常椅子 | H40: 不可 | I40: 私語厳禁 | J40: 飲み物のみ | K40: なし | M40: 椅子：背もたれあり。飲み物は蓋付きのみ可。 | O40: 2026-09-25 | P40: 久保田 | Q40: 実験D調査報告書(2026-09-25)＋佐藤 聞き取り（静粛性）＋閲覧室図書館_ver2.xlsx | R40: =IF(AND(ISNUMBER(E40),ISNUMBER(F40),E40>0),F40/E40,"") -> 0
A41: S039 | B41: 図書館 | C41: 1 | D41: 入り口正面 | E41: 4 | F41: 0 | G41: クッション椅子 | H41: 不可 | I41: 私語厳禁 | J41: 飲み物のみ | K41: なし | M41: 椅子：背もたれあり・やわらかい。飲み物は蓋付きのみ可。電源はあるが使用できない。 | O41: 2026-09-25 | P41: 久保田 | Q41: 実験D調査報告書(2026-09-25)＋佐藤 聞き取り（静粛性）＋閲覧室図書館_ver2.xlsx | R41: =IF(AND(ISNUMBER(E41),ISNUMBER(F41),E41>0),F41/E41,"") -> 0
A42: S040 | B42: 図書館 | C42: 1 | D42: ラウンジ席 | E42: 9 | F42: 0 | G42: スツール | H42: 不可 | I42: 私語厳禁 | J42: 飲み物のみ | K42: なし | M42: 椅子：背もたれなし。飲み物は蓋付きのみ可。 | O42: 2026-09-25 | P42: 久保田 | Q42: 実験D調査報告書(2026-09-25)＋佐藤 聞き取り（静粛性）＋閲覧室図書館_ver2.xlsx | R42: =IF(AND(ISNUMBER(E42),ISNUMBER(F42),E42>0),F42/E42,"") -> 0
A43: S041 | B43: 図書館 | C43: 2 | D43: 階段上がってすぐ スタンドアップデスク | E43: 6 | F43: 8 | G43: なし | H43: 可 | I43: 私語厳禁 | J43: 飲み物のみ | K43: あり | L43: 各辺に2口（1口あたり2タップ） | M43: 椅子：椅子なし。飲み物は蓋付きのみ可。6人用のスタンドアップデスク。 | O43: 2026-09-25 | P43: 久保田 | Q43: 実験D調査報告書(2026-09-25)＋佐藤 聞き取り（静粛性）＋閲覧室図書館_ver2.xlsx | R43: =IF(AND(ISNUMBER(E43),ISNUMBER(F43),E43>0),F43/E43,"") -> 1.3333333
A44: S042 | B44: 図書館 | C44: 2 | D44: ソファ席 | E44: 8 | F44: 0 | G44: ソファ | H44: 不可 | I44: 私語厳禁 | J44: 飲み物のみ | K44: なし | M44: 椅子：やわらかい・背もたれあり。飲み物は蓋付きのみ可。 | O44: 2026-09-25 | P44: 久保田 | Q44: 実験D調査報告書(2026-09-25)＋佐藤 聞き取り（静粛性）＋閲覧室図書館_ver2.xlsx | R44: =IF(AND(ISNUMBER(E44),ISNUMBER(F44),E44>0),F44/E44,"") -> 0
A45: S043 | B45: 図書館 | C45: 2 | D45: 階段右手 | E45: 47 | F45: 0 | G45: 通常椅子 | H45: 不可 | I45: 私語厳禁 | J45: 飲み物のみ | K45: なし | M45: 椅子：背もたれあり・普通。飲み物は蓋付きのみ可。 | O45: 2026-09-25 | P45: 久保田 | Q45: 実験D調査報告書(2026-09-25)＋佐藤 聞き取り（静粛性）＋閲覧室図書館_ver2.xlsx | R45: =IF(AND(ISNUMBER(E45),ISNUMBER(F45),E45>0),F45/E45,"") -> 0
A46: S044 | B46: 図書館 | C46: 2 | D46: 階段周辺のチェア | E46: 6 | F46: 0 | G46: 通常椅子 | H46: 不可 | I46: 私語厳禁 | J46: 飲み物のみ | K46: なし | M46: 椅子：背もたれあり・ひじ掛けと小さなテーブル付き。飲み物は蓋付きのみ可。 | O46: 2026-09-25 | P46: 久保田 | Q46: 実験D調査報告書(2026-09-25)＋佐藤 聞き取り（静粛性）＋閲覧室図書館_ver2.xlsx | R46: =IF(AND(ISNUMBER(E46),ISNUMBER(F46),E46>0),F46/E46,"") -> 0
A47: S045 | B47: 図書館 | C47: 2 | D47: 個人研究室を挟んだ反対側のチェア | E47: 12 | F47: 0 | G47: 通常椅子 | H47: 不可 | I47: 私語厳禁 | J47: 飲み物のみ | K47: なし | M47: 椅子：背もたれあり・ひじ掛けと小さなテーブル付き。飲み物は蓋付きのみ可。 | O47: 2026-09-25 | P47: 久保田 | Q47: 実験D調査報告書(2026-09-25)＋佐藤 聞き取り（静粛性）＋閲覧室図書館_ver2.xlsx | R47: =IF(AND(ISNUMBER(E47),ISNUMBER(F47),E47>0),F47/E47,"") -> 0
A48: S046 | B48: 図書館 | C48: 2 | D48: 壁沿いデスク | E48: 112 | F48: 76 | G48: 通常椅子 | H48: 不可 | I48: 私語厳禁 | J48: 飲み物のみ | K48: なし | L48: 3席あたり1口（2タップ） | M48: 椅子：背もたれあり・普通。飲み物は蓋付きのみ可。3人掛け36台・2人掛け2台。図書館で電源が使える座席のほとんどがここ。 | O48: 2026-09-25 | P48: 久保田 | Q48: 実験D調査報告書(2026-09-25)＋佐藤 聞き取り（静粛性）＋閲覧室図書館_ver2.xlsx | R48: =IF(AND(ISNUMBER(E48),ISNUMBER(F48),E48>0),F48/E48,"") -> 0.67857143
A49: S047 | B49: 図書館 | C49: 2 | D49: 2階南 右側 | E49: 52 | F49: 0 | G49: 通常椅子 | H49: 不可 | I49: 私語厳禁 | J49: 飲み物のみ | K49: なし | M49: 椅子：背もたれあり・普通。飲み物は蓋付きのみ可。 | O49: 2026-09-25 | P49: 久保田 | Q49: 実験D調査報告書(2026-09-25)＋佐藤 聞き取り（静粛性）＋閲覧室図書館_ver2.xlsx | R49: =IF(AND(ISNUMBER(E49),ISNUMBER(F49),E49>0),F49/E49,"") -> 0
A50: S048 | B50: 図書館 | C50: 2 | D50: 参考図書（000〜999）横 | E50: 2 | F50: 0 | G50: クッション椅子 | H50: 不可 | I50: 私語厳禁 | J50: 飲み物のみ | K50: なし | M50: 椅子：やわらかい・背もたれあり。飲み物は蓋付きのみ可。 | O50: 2026-09-25 | P50: 久保田 | Q50: 実験D調査報告書(2026-09-25)＋佐藤 聞き取り（静粛性）＋閲覧室図書館_ver2.xlsx | R50: =IF(AND(ISNUMBER(E50),ISNUMBER(F50),E50>0),F50/E50,"") -> 0
...

Sheet 選択肢
A1: chair_type | B1: standing | C1: quietness | D1: food | E1: task_light
A2: 木製椅子 | B2: 可 | C2: 私語厳禁 | D2: 不可 | E2: あり
A3: 通常椅子 | B3: 不可 | C3: 小声可 | D3: 飲み物のみ | E3: なし
A4: クッション椅子 | C4: 会話可 | D4: 食事可 | E4: 未調査
A5: キャスター付き椅子 | C5: 通話可 | D5: 未調査
A6: 机一体型 | C6: 未調査
A7: ソファ
A8: スツール
A9: なし
A10: 未調査
A13: 「未調査」は取込時に条件検索の対象外として扱う想定。通常椅子＝背もたれのある普通の椅子、スツール＝背もたれなし。

Sheet 要確認
A1: 対象ID | B1: 項目 | C1: 対象 | D1: 内容 | E1: 対応
A2: - | B2: - | C2: 講義棟 K510・K601 | D2: 元データで「使用不可」。スポットから除外した。 | E2: 恒久的に使えないのか、一時的か確認
A3: S028 | B3: seats | C3: K706 | D3: 座席数が空欄。 | E3: 再調査して記入
A4: S023〜S027 | B4: outlets | C4: K701〜K705 | D4: コンセント220口に対し座席160席。他の講義室（10口）と桁が違う。 | E4: 入力ミスでないか確認
A5: 講義棟全27室 | B5: task_light | C5: 講義棟 | D5: 作業灯が未調査。（静粛性・飲食可否は佐藤の確認により「会話可」「食事可」に更新済み） | E5: 調査して記入
A6: 閲覧室・自習室 | B6: building / floor | C6: 閲覧室・自習室 | D6: 閲覧室は1階と判明したが、建物名が未記入。自習室は建物名・階とも未記入。 | E6: 建物名（自習室は階も）を記入
A7: 自習室 | B7: quietness / food | C7: 自習室 | D7: 自習室の静粛性・飲食可否が未調査（閲覧室・図書館はver2と佐藤の確認で記入済み）。 | E7: 調査して記入
A8: S032 | B8: outlets | C8: 閲覧室 6人掛けデスク | D8: 元データ「座席間に1口（タップ4×2＝8個）」を1台あたり8タップと解釈し、8×21台＝168とした。 | E8: 1台あたりか合計かを調査者に確認
A9: S033 | B9: outlets | C9: 閲覧室 2人掛けデスク | D9: 「タップ2個」を1台あたりと解釈し、2×14台＝28とした。 | E9: 同上
A10: S046 | B10: outlets | C10: 図書館2階 壁沿いデスク | D10: 「3席あたり1口（2タップ）」から、38口×2タップ＝76とした。2人掛け2台も1口ずつと仮定。 | E10: 調査者に確認
A11: 21号館4件 | B11: outlets | C11: 21号館 | D11: 「2×7」を2口×7か所＝14口と解釈した（他も同様）。 | E11: 調査者に確認
A12: S003, S004 | B12: chair_type | C12: 21号館 スタディプラザ | D12: 「座り心地はいい」を「クッション椅子」に分類した。 | E12: 椅子の種類を確認
... A21: 自習室 | B21: chair_type / task_light | C21: 自習室 | D21: ver2に自習室のシートがなく、椅子・作業灯が未調査のまま。 | E21: 調査して記入

Sheet 集計
A1: 建物 | B1: スポット数 | C1: 座席数 | D1: コンセント数
A2: 21号館 | B2: =COUNTIF(spots!$B$3:$B$52,A2) -> 4 | C2: =SUMIF(spots!$B$3:$B$52,A2,spots!$E$3:$E$52) -> 92 | D2: =SUMIF(spots!$B$3:$B$52,A2,spots!$F$3:$F$52) -> 42
A3: 講義棟 | B3: =COUNTIF(spots!$B$3:$B$52,A3) -> 27 | C3: =SUMIF(spots!$B$3:$B$52,A3,spots!$E$3:$E$52) -> 3402 | D3: =SUMIF(spots!$B$3:$B$52,A3,spots!$F$3:$F$52) -> 1320
A4: 閲覧室（建物未記入） | B4: =COUNTIF(spots!$B$3:$B$52,A4) -> 5 | C4: =SUMIF(spots!$B$3:$B$52,A4,spots!$E$3:$E$52) -> 182 | D4: =SUMIF(spots!$B$3:$B$52,A4,spots!$F$3:$F$52) -> 196
A5: 自習室（建物未記入） | B5: =COUNTIF(spots!$B$3:$B$52,A5) -> 1 | C5: =SUMIF(spots!$B$3:$B$52,A5,spots!$E$3:$E$52) -> 60 | D5: =SUMIF(spots!$B$3:$B$52,A5,spots!$F$3:$F$52) -> 0
A6: 図書館 | B6: =COUNTIF(spots!$B$3:$B$52,A6) -> 13 | C6: =SUMIF(spots!$B$3:$B$52,A6,spots!$E$3:$E$52) -> 498 | D6: =SUMIF(spots!$B$3:$B$52,A6,spots!$F$3:$F$52) -> 84
A7: 計 | B7: =SUM(B2:B6) -> 50 | C7: =SUM(C2:C6) -> 4234 | D7: =SUM(D2:D6) -> 1642

Sheet reservations
A1: date | B1: weekday | C1: room | D1: start | E1: end | F1: periods | G1: duplicate | H1: spot_id
A2: 日付 | B2: 曜日 | C2: 教室 | D2: 開始 | E2: 終了 | F2: 該当時限（1〜5限） | G2: 重複予約 | H2: 対応スポット
A3: 2026-10-02 | B3: 金 | C3: 1211 | D3: 08:50 | E3: 10:20 | F3: 1
A4: 2026-10-02 | B4: 金 | C4: 1211 | D4: 10:30 | E4: 12:00 | F4: 2
A5: 2026-10-02 | B5: 金 | C5: 1211 | D5: 18:00 | E5: 21:00
A6: 2026-10-02 | B6: 金 | C6: 2131PC室 | D6: 10:30 | E6: 12:00 | F6: 2
A7: 2026-10-02 | B7: 金 | C7: 2131PC室 | D7: 13:00 | E7: 14:30 | F7: 3
A8: 2026-10-02 | B8: 金 | C8: 2131PC室 | D8: 14:40 | E8: 16:10 | F8: 4
A9: 2026-10-02 | B9: 金 | C9: 2131PC室 | D9: 16:20 | E9: 17:50 | F9: 5
A10: 2026-10-02 | B10: 金 | C10: 2131PC室 | D10: 18:10 | E10: 19:40
A11: 2026-10-02 | B11: 金 | C11: 232PC室 | D11: 16:20 | E11: 17:50 | F11: 5
A12: 2026-10-02 | B12: 金 | C12: 444 | D12: 08:50 | E12: 10:20 | F12: 1
A13: 2026-10-02 | B13: 金 | C13: 444 | D13: 13:00 | E13: 14:30 | F13: 3
A14: 2026-10-02 | B14: 金 | C14: 444 | D14: 14:40 | E14: 16:10 | F14: 4
A15: 2026-10-02 | B15: 金 | C15: 444 | D15: 16:20 | E15: 17:50 | F15: 5
A16: 2026-10-02 | B16: 金 | C16: 445 | D16: 10:30 | E16: 12:00 | F16: 2
A17: 2026-10-02 | B17: 金 | C17: 611PC室 | D17: 08:50 | E17: 10:20 | F17: 1
A18: 2026-10-02 | B18: 金 | C18: 611PC室 | D18: 10:30 | E18: 12:00 | F18: 2
A19: 2026-10-02 | B19: 金 | C19: 611PC室 | D19: 13:00 | E19: 14:30 | F19: 3
A20: 2026-10-02 | B20: 金 | C20: 611PC室 | D20: 14:40 | E20: 15:20 | F20: 4
A21: 2026-10-02 | B21: 金 | C21: 612PC室 | D21: 15:30 | E21: 16:10 | F21: 4
A22: 2026-10-02 | B22: 金 | C22: 612PC室 | D22: 16:20 | E22: 17:50 | F22: 5
... A32: 2026-10-02 | B32: 金 | C32: 7407 | D32: 10:30 | E32: 12:00 | F32: 2
A33: 2026-10-02 | B33: 金 | C33: 7407 | D33: 13:00 | E33: 14:30 | F33: 3 | G33: あり
A34: 2026-10-02 | B34: 金 | C34: 7407 | D34: 16:20 | E34: 17:50 | F34: 5 | G34: あり
A35: 2026-10-02 | B35: 金 | C35: 7411 | D35: 08:50 | E35: 17:50 | F35: 1,2,3,4,5
A36: 2026-10-02 | B36: 金 | C36: K101 | D36: 08:50 | E36: 10:20 | F36: 1
A37: 2026-10-02 | B37: 金 | C37: K101 | D37: 10:30 | E37: 12:00 | F37: 2
A38: 2026-10-02 | B38: 金 | C38: K101 | D38: 13:00 | E38: 14:30 | F38: 3
A39: 2026-10-02 | B39: 金 | C39: K101 | D39: 14:40 | E39: 16:10 | F39: 4
A40: 2026-10-02 | B40: 金 | C40: K101 | D40: 16:20 | E40: 17:50 | F40: 5
A41: 2026-10-02 | B41: 金 | C41: K101 | D41: 18:00 | E41: 21:00
A42: 2026-10-02 | B42: 金 | C42: K102 | D42: 08:50 | E42: 10:20 | F42: 1
A43: 2026-10-02 | B43: 金 | C43: K102 | D43: 10:30 | E43: 12:00 | F43: 2
A44: 2026-10-02 | B44: 金 | C44: K102 | D44: 13:00 | E44: 14:30 | F44: 3
A45: 2026-10-02 | B45: 金 | C45: K102 | D45: 14:40 | E45: 16:10 | F45: 4
A46: 2026-10-02 | B46: 金 | C46: K102 | D46: 16:20 | E46: 18:25 | F46: 5
A47: 2026-10-02 | B47: 金 | C47: K103 | D47: 08:50 | E47: 10:20 | F47: 1
A48: 2026-10-02 | B48: 金 | C48: K103 | D48: 10:30 | E48: 12:00 | F48: 2
A49: 2026-10-02 | B49: 金 | C49: K103 | D49: 13:00 | E49: 14:30 | F49: 3
...
